Workbook

Sheet M_YT_LIVE
A1: ID | B1: 配信日 | C1: タイトル | D1: URL | F1: 音源区分
A2: =ROW()-1 -> 1 | B2: 45774 | C2: 【初配信】おばけじゃないから、怖くないよ〜.。o○【幽音しの:ななしいんく】 | D2: https://www.youtube.com/live/rPoEadXC5ck?si=PyjsfpuwHgwH2fjV | F2: 他
A3: =ROW()-1 -> 2 | B3: 45775 | C3: 【雑談】今日こそはアップのしのを見せます！！【幽音しの:ななしいんく】 | D3: https://www.youtube.com/live/ManpEHIFXt8?si=FaF-JgKp6sZN0EAV | F3: 他
A4: =ROW()-1 -> 3 | B4: 45776 | C4: 【弾き語り】あったかいので、春に聞きたい歌を歌う日です！！【幽音しの:ななしいんく】 | D4: https://www.youtube.com/live/UnI_NxQlyr8?si=2zvgEeRPzShWMpBP | F4: 弾き語り
A5: =ROW()-1 -> 4 | B5: 45778 | C5: 【弾き語り】夜にピッタリな曲を歌っていきます！！【幽音しの:ななしいんく】 | D5: https://www.youtube.com/live/qX9bxWpkH6E?si=OkODsP1XDKgR0qeY | F5: 弾き語り
A6: =ROW()-1 -> 5 | B6: 45779 | C6: 【マイクラ】いざ！！はじめてのななしマイクラへ！【幽音しの:ななしいんく】 | D6: https://www.youtube.com/live/teQHty590Zo?si=v5B1y_6kXfHA0GoX | F6: 他
A7: =ROW()-1 -> 6 | B7: 45782 | C7: 【弾き語り】ボカロ多めの弾き語り歌枠！！【幽音しの:ななしいんく】 | D7: https://www.youtube.com/live/kbdEHcoJcQs?si=VS3EodMJVsy1DVZQ | F7: 弾き語り
A8: =ROW()-1 -> 7 | B8: 45782 | C8: 【弾き語り】ボカロ多めの弾き語り歌枠！！【幽音しの:ななしいんく】 | D8: https://www.youtube.com/live/BIOCmyo4mQU?si=mUE7u0kM5d94T-4A | F8: 弾き語り
A9: =ROW()-1 -> 8 | B9: 45785 | C9: 【Cチームコラボ】ガーティックフォンやっていくぞ～！【幽音しの:ななしいんく】 | D9: https://www.youtube.com/live/4-U-XxXCyOM?si=BEJWFGAa9QkkJd2W | F9: 他
A10: =ROW()-1 -> 9 | B10: 45785 | C10: 【弾き語り】チルタイム！夜の弾き語り歌枠！！【幽音しの:ななしいんく】 | D10: https://www.youtube.com/live/gtzKshYmOXY?si=1Gz8lwbOe32zbbqo | F10: 弾き語り
A11: =ROW()-1 -> 10 | B11: 45787 | C11: 【マインクラフト】のんびりやっていく！！うーぱー捕まえてから考える【幽音しの:ななしいんく】 | D11: https://www.youtube.com/live/kdlYMlLAv-0?si=_bP0uWXKt4eYdLz1 | F11: 他
A12: =ROW()-1 -> 11 | B12: 45788 | C12: 【弾き語り】回線テスト ゲリラ！【幽音しの:ななしいんく】 | D12: https://www.youtube.com/live/Fd1Z_6ywMyI?si=i1-U-h_G5BWB0Lq- | F12: 弾き語り
A13: =ROW()-1 -> 12 | B13: 45791 | C13: 【祝！収益化】君たちのおかげだよ～～！しのの好きな歌を弾き語りしていく！！！【幽音しの:ななしいんく】 | D13: https://www.youtube.com/live/0d6TiZm7xWc?si=rSfrknMqNQFcz5xw | F13: 弾き語り
... A25: =ROW()-1 -> 24 | B25: 45813 | C25: 【弾き語り】深夜定期!! 今日は必ずチルで弾き語りしていく～～！！！【幽音しの:ななしいんく】 | D25: https://www.youtube.com/live/Us_EP0LuOUI?si=QKfLbi9NsZLi9sIi | F25: 弾き語り
A26: 25 | B26: 45814 | C26: 【音源歌枠】95点チャレンジしていく！歌うぞ～～～！【幽音しの:ななしいんく】 | D26: https://www.youtube.com/live/E8l1nOoKLLI?si=9GMtlAOzsgHxbniX | F26: 音源
A27: =ROW()-1 -> 26 | B27: 45817 | C27: 【弾き語り】 げりらりら歌枠【幽音しの:ななしいんく】 | D27: https://www.youtube.com/live/T2z_BAhLZz0?si=FZhoxASjxucX4Rxr | F27: 弾き語り
A28: =ROW()-1 -> 27 | B28: 45817 | C28: 【弾き語り】 夜に歌う弾き語り～～～！！！！！【幽音しの:ななしいんく】 | D28: https://www.youtube.com/live/OEtLBen9pLM?si=M4WDMSGkkHfWLvDr | F28: 弾き語り
A29: =ROW()-1 -> 28 | B29: 45822 | C29: 【コラボ】初めてだけど余裕でしょ！！！！！！完全爆弾解除マニュアル：Keep Talking and Nobody Explodes【幽音しの:ななしいんく】 | D29: https://www.youtube.com/live/kAN03C_u2wk?si=C3MgRUb2uxI_lKRp | F29: 他
A30: =ROW()-1 -> 29 | B30: 45823 | C30: 【弾き語り】深夜定期でゆったりしていく 夜に聞きたい曲を！！！【幽音しの:ななしいんく】 | D30: https://www.youtube.com/live/wEZHgaS4eCg?si=_Rpt2MlexrsFC7dZ | F30: 弾き語り
A31: =ROW()-1 -> 30 | B31: 45825 | C31: 【歌枠】アニソン縛りで歌っていきます！【幽音しの:ななしいんく】 #新人vtuber / #vsinger | D31: https://www.youtube.com/live/GvGh24EJfGg?si=QLYBryRLPz4v_Qdl | F31: 音源
A32: =ROW()-1 -> 31 | B32: 45826 | C32: 【DON'T SCREAM】懺悔ホラー！見守りありでやる 【幽音しの:ななしいんく】 #新人vtuber | D32: https://www.youtube.com/live/_LQ7HdUNq5w?si=qZDGfBAezmmueivV | F32: 他
A33: =ROW()-1 -> 32 | B33: 45827 | C33: 【ゲーム】少しつぼおじを触っていく！ Getting Over It【幽音しの:ななしいんく】 #新人vtuber | D33: https://www.youtube.com/live/XVZw9I6yZAg?si=cSpTyiDaBFkw_KqY | F33: 他
A34: =ROW()-1 -> 33 | B34: 45835 | C34: 【弾き語り】深夜定期！眠れる歌枠をどうぞ【幽音しの:ななしいんく】 #新人vtuber / #vsinger | D34: https://www.youtube.com/live/6wh0qjbo6K4?si=vntI9mYE52ZplV6U | F34: 弾き語り
A35: =ROW()-1 -> 34 | B35: 45840 | C35: 【 Backrooms #あましの】恐ろしいものが潜んでいるってホント？Escape the Backrooms 【幽音しの:ななしいんく】 #新人vtuber / #vsinger | D35: https://www.youtube.com/live/Wm8SJ2In5hk?si=hIb5ii9nQxkobaIG | F35: 他
A36: =ROW()-1 -> 35 | B36: 45841 | C36: 【コラボ】エンドラ討伐！！！！【幽音しの:ななしいんく】 #新人vtuber / #vsinger | D36: https://www.youtube.com/live/3i9yjRs0_a8?si=lfqOrG-slxFf5TMM | F36: 他
A37: =ROW()-1 -> 36 | B37: 45842 | C37: 【カラオケ！】初めての縦型歌枠！お昼だからね…！【幽音しの:ななしいんく】 #新人vtuber / #vsinger | D37: https://www.youtube.com/live/cHLqE4AOOjI?si=heDnYTUAoUpLyQ_J | F37: 音源
A38: =ROW()-1 -> 37 | B38: 45843 | C38: 【弾き語り】定期！弾き語りでゆっくりしていかない？【幽音しの:ななしいんく】 #新人vtuber / #vsinger | D38: https://www.youtube.com/live/wY3z5W9B8N0?si=FVqBjyoCdmcOKFxz | F38: 弾き語り
... A111: =ROW()-1 -> 110 | B111: 45966 | C111: 【夜ご飯食べよう】ハンバーグ、ポテサラ、パルム編【幽音しの:ななしいんく】 #vtuber #vsinger | D111: https://www.youtube.com/live/t1MyU2Fl5wo?si=9kE5U1BS2VkZhy-y | F111: 他
A112: =ROW()-1 -> 111
A113: =ROW()-1 -> 112
A114: =ROW()-1 -> 113
A115: =ROW()-1 -> 114
A116: =ROW()-1 -> 115
A117: =ROW()-1 -> 116
A118: =ROW()-1 -> 117
A119: =ROW()-1 -> 118
A120: =ROW()-1 -> 119
A121: =ROW()-1 -> 120
A122: =ROW()-1 -> 121
A123: =ROW()-1 -> 122
...

Sheet M_YT_LIVE_TIMESTAMP
A1: ID | B1: LIVE_ID | C1: タイムスタンプ | D1: 曲名 | E1: アーティスト | G1: 配信音源区分 | W1: タイムスタンプ秒 | X1: URL | Z1: リンク | AA1: key
A2: 1 | B2: 1 | C2: 0:01:47 | D2: かすかなおと | E2: 幽音しの | G2: =_xlfn.XLOOKUP(B2,M_YT_LIVE!A:A,M_YT_LIVE!F:F,"ERROR",0,1) -> 他 | W2: =TIMEVALUE($C2)*86400 -> 107 | X2: =_xlfn.XLOOKUP($B2,M_YT_LIVE!$A:$A,M_YT_LIVE!$D:$D) -> https://www.youtube.com/live/rPoEadXC5ck?si=PyjsfpuwHgwH2fjV | Z2: =HYPERLINK($X2&SUBSTITUTE(マスタ!$C$3,"XXXXX",$W2)) -> https://www.youtube.com/live/rPoEadXC5ck?si=PyjsfpuwHgwH2fjV&t=107s | AA2: =TRIM(E2)&TRIM(D2) -> 幽音しのかすかなおと
A3: 2 | B3: 1 | C3: 0:03:13 | D3: 怪獣の花唄 | E3: Vaundy | G3: =_xlfn.XLOOKUP(B3,M_YT_LIVE!A:A,M_YT_LIVE!F:F,"ERROR",0,1) -> 他 | W3: =TIMEVALUE($C3)*86400 -> 193 | X3: =_xlfn.XLOOKUP($B3,M_YT_LIVE!$A:$A,M_YT_LIVE!$D:$D) -> https://www.youtube.com/live/rPoEadXC5ck?si=PyjsfpuwHgwH2fjV | Z3: =HYPERLINK($X3&SUBSTITUTE(マスタ!$C$3,"XXXXX",$W3)) -> https://www.youtube.com/live/rPoEadXC5ck?si=PyjsfpuwHgwH2fjV&t=193s | AA3: =TRIM(E3)&TRIM(D3) -> Vaundy怪獣の花唄
A4: 3 | B4: 1 | C4: 0:26:45 | D4: 初配信兼入浴の歌 | E4: 幽音しの(即興) | G4: =_xlfn.XLOOKUP(B4,M_YT_LIVE!A:A,M_YT_LIVE!F:F,"ERROR",0,1) -> 他 | W4: =TIMEVALUE($C4)*86400 -> 1605 | X4: =_xlfn.XLOOKUP($B4,M_YT_LIVE!$A:$A,M_YT_LIVE!$D:$D) -> https://www.youtube.com/live/rPoEadXC5ck?si=PyjsfpuwHgwH2fjV | Z4: =HYPERLINK($X4&SUBSTITUTE(マスタ!$C$3,"XXXXX",$W4)) -> https://www.youtube.com/live/rPoEadXC5ck?si=PyjsfpuwHgwH2fjV&t=1605s | AA4: =TRIM(E4)&TRIM(D4) -> 幽音しの(即興)初配信兼入浴の歌
A5: =ROW()-1 -> 4 | B5: 3 | C5: 0:06:09 | D5: 憂、燦々 | E5: クリープハイプ | G5: =_xlfn.XLOOKUP(B5,M_YT_LIVE!A:A,M_YT_LIVE!F:F,"ERROR",0,1) -> 弾き語り | W5: =TIMEVALUE($C5)*86400 -> 369 | X5: =_xlfn.XLOOKUP($B5,M_YT_LIVE!$A:$A,M_YT_LIVE!$D:$D) -> https://www.youtube.com/live/UnI_NxQlyr8?si=2zvgEeRPzShWMpBP | Z5: =HYPERLINK($X5&SUBSTITUTE(マスタ!$C$3,"XXXXX",$W5)) -> https://www.youtube.com/live/UnI_NxQlyr8?si=2zvgEeRPzShWMpBP&t=369s | AA5: =TRIM(E5)&TRIM(D5) -> クリープハイプ憂、燦々
A6: =ROW()-1 -> 5 | B6: 3 | C6: 0:15:28 | D6: プラトニック・ラヴ | E6: メル feat.IA | G6: =_xlfn.XLOOKUP(B6,M_YT_LIVE!A:A,M_YT_LIVE!F:F,"ERROR",0,1) -> 弾き語り | W6: =TIMEVALUE($C6)*86400 -> 928 | X6: =_xlfn.XLOOKUP($B6,M_YT_LIVE!$A:$A,M_YT_LIVE!$D:$D) -> https://www.youtube.com/live/UnI_NxQlyr8?si=2zvgEeRPzShWMpBP | Z6: =HYPERLINK($X6&SUBSTITUTE(マスタ!$C$3,"XXXXX",$W6)) -> https://www.youtube.com/live/UnI_NxQlyr8?si=2zvgEeRPzShWMpBP&t=928s | AA6: =TRIM(E6)&TRIM(D6) -> メル feat.IAプラトニック・ラヴ
A7: =ROW()-1 -> 6 | B7: 3 | C7: 0:22:59 | D7: さようなら、花泥棒さん | E7: メル feat.初音ミク | G7: =_xlfn.XLOOKUP(B7,M_YT_LIVE!A:A,M_YT_LIVE!F:F,"ERROR",0,1) -> 弾き語り | W7: =TIMEVALUE($C7)*86400 -> 1379 | X7: =_xlfn.XLOOKUP($B7,M_YT_LIVE!$A:$A,M_YT_LIVE!$D:$D) -> https://www.youtube.com/live/UnI_NxQlyr8?si=2zvgEeRPzShWMpBP | Z7: =HYPERLINK($X7&SUBSTITUTE(マスタ!$C$3,"XXXXX",$W7)) -> https://www.youtube.com/live/UnI_NxQlyr8?si=2zvgEeRPzShWMpBP&t=1379s | AA7: =TRIM(E7)&TRIM(D7) -> メル feat.初音ミクさようなら、花泥棒さん
A8: =ROW()-1 -> 7 | B8: 3 | C8: 0:31:28 | D8: 踊り子 | E8: Vaundy | G8: =_xlfn.XLOOKUP(B8,M_YT_LIVE!A:A,M_YT_LIVE!F:F,"ERROR",0,1) -> 弾き語り | W8: =TIMEVALUE($C8)*86400 -> 1888 | X8: =_xlfn.XLOOKUP($B8,M_YT_LIVE!$A:$A,M_YT_LIVE!$D:$D) -> https://www.youtube.com/live/UnI_NxQlyr8?si=2zvgEeRPzShWMpBP | Z8: =HYPERLINK($X8&SUBSTITUTE(マスタ!$C$3,"XXXXX",$W8)) -> https://www.youtube.com/live/UnI_NxQlyr8?si=2zvgEeRPzShWMpBP&t=1888s | AA8: =TRIM(E8)&TRIM(D8) -> Vaundy踊り子
A9: =ROW()-1 -> 8 | B9: 3 | C9: 0:41:18 | D9: 春擬き | E9: やなぎなぎ | G9: =_xlfn.XLOOKUP(B9,M_YT_LIVE!A:A,M_YT_LIVE!F:F,"ERROR",0,1) -> 弾き語り | W9: =TIMEVALUE($C9)*86400 -> 2478 | X9: =_xlfn.XLOOKUP($B9,M_YT_LIVE!$A:$A,M_YT_LIVE!$D:$D) -> https://www.youtube.com/live/UnI_NxQlyr8?si=2zvgEeRPzShWMpBP | Z9: =HYPERLINK($X9&SUBSTITUTE(マスタ!$C$3,"XXXXX",$W9)) -> https://www.youtube.com/live/UnI_NxQlyr8?si=2zvgEeRPzShWMpBP&t=2478s | AA9: =TRIM(E9)&TRIM(D9) -> やなぎなぎ春擬き
A10: =ROW()-1 -> 9 | B10: 3 | C10: 0:51:17 | D10: CHE.R.RY | E10: YUI | G10: =_xlfn.XLOOKUP(B10,M_YT_LIVE!A:A,M_YT_LIVE!F:F,"ERROR",0,1) -> 弾き語り | W10: =TIMEVALUE($C10)*86400 -> 3077 | X10: =_xlfn.XLOOKUP($B10,M_YT_LIVE!$A:$A,M_YT_LIVE!$D:$D) -> https://www.youtube.com/live/UnI_NxQlyr8?si=2zvgEeRPzShWMpBP | Z10: =HYPERLINK($X10&SUBSTITUTE(マスタ!$C$3,"XXXXX",$W10)) -> https://www.youtube.com/live/UnI_NxQlyr8?si=2zvgEeRPzShWMpBP&t=3077s | AA10: =TRIM(E10)&TRIM(D10) -> YUICHE.R.RY
A11: =ROW()-1 -> 10 | B11: 3 | C11: 1:00:20 | D11: 春泥棒 | E11: ヨルシカ | G11: =_xlfn.XLOOKUP(B11,M_YT_LIVE!A:A,M_YT_LIVE!F:F,"ERROR",0,1) -> 弾き語り | W11: =TIMEVALUE($C11)*86400 -> 3620 | X11: =_xlfn.XLOOKUP($B11,M_YT_LIVE!$A:$A,M_YT_LIVE!$D:$D) -> https://www.youtube.com/live/UnI_NxQlyr8?si=2zvgEeRPzShWMpBP | Z11: =HYPERLINK($X11&SUBSTITUTE(マスタ!$C$3,"XXXXX",$W11)) -> https://www.youtube.com/live/UnI_NxQlyr8?si=2zvgEeRPzShWMpBP&t=3620s | AA11: =TRIM(E11)&TRIM(D11) -> ヨルシカ春泥棒
A12: =ROW()-1 -> 11 | B12: 4 | C12: 0:05:55 | D12: ヒカリヘ | E12: miwa | G12: =_xlfn.XLOOKUP(B12,M_YT_LIVE!A:A,M_YT_LIVE!F:F,"ERROR",0,1) -> 弾き語り | W12: =TIMEVALUE($C12)*86400 -> 355 | X12: =_xlfn.XLOOKUP($B12,M_YT_LIVE!$A:$A,M_YT_LIVE!$D:$D) -> https://www.youtube.com/live/qX9bxWpkH6E?si=OkODsP1XDKgR0qeY | Z12: =HYPERLINK($X12&SUBSTITUTE(マスタ!$C$3,"XXXXX",$W12)) -> https://www.youtube.com/live/qX9bxWpkH6E?si=OkODsP1XDKgR0qeY&t=355s | AA12: =TRIM(E12)&TRIM(D12) -> miwaヒカリヘ
A13: =ROW()-1 -> 12 | B13: 4 | C13: 0:13:23 | D13: more than words | E13: 羊文学 | G13: =_xlfn.XLOOKUP(B13,M_YT_LIVE!A:A,M_YT_LIVE!F:F,"ERROR",0,1) -> 弾き語り | W13: =TIMEVALUE($C13)*86400 -> 803 | X13: =_xlfn.XLOOKUP($B13,M_YT_LIVE!$A:$A,M_YT_LIVE!$D:$D) -> https://www.youtube.com/live/qX9bxWpkH6E?si=OkODsP1XDKgR0qeY | Z13: =HYPERLINK($X13&SUBSTITUTE(マスタ!$C$3,"XXXXX",$W13)) -> https://www.youtube.com/live/qX9bxWpkH6E?si=OkODsP1XDKgR0qeY&t=803s | AA13: =TRIM(E13)&TRIM(D13) -> 羊文学more than words
A14: =ROW()-1 -> 13 | B14: 4 | C14: 0:21:20 | D14: お気に召すまま | E14: Eve feat.初音ミク | G14: =_xlfn.XLOOKUP(B14,M_YT_LIVE!A:A,M_YT_LIVE!F:F,"ERROR",0,1) -> 弾き語り | W14: =TIMEVALUE($C14)*86400 -> 1280 | X14: =_xlfn.XLOOKUP($B14,M_YT_LIVE!$A:$A,M_YT_LIVE!$D:$D) -> https://www.youtube.com/live/qX9bxWpkH6E?si=OkODsP1XDKgR0qeY | Z14: =HYPERLINK($X14&SUBSTITUTE(マスタ!$C$3,"XXXXX",$W14)) -> https://www.youtube.com/live/qX9bxWpkH6E?si=OkODsP1XDKgR0qeY&t=1280s | AA14: =TRIM(E14)&TRIM(D14) -> Eve feat.初音ミクお気に召すまま
A15: =ROW()-1 -> 14 | B15: 4 | C15: 0:28:43 | D15: Laugh away | E15: YUI | G15: =_xlfn.XLOOKUP(B15,M_YT_LIVE!A:A,M_YT_LIVE!F:F,"ERROR",0,1) -> 弾き語り | W15: =TIMEVALUE($C15)*86400 -> 1723 | X15: =_xlfn.XLOOKUP($B15,M_YT_LIVE!$A:$A,M_YT_LIVE!$D:$D) -> https://www.youtube.com/live/qX9bxWpkH6E?si=OkODsP1XDKgR0qeY | Z15: =HYPERLINK($X15&SUBSTITUTE(マスタ!$C$3,"XXXXX",$W15)) -> https://www.youtube.com/live/qX9bxWpkH6E?si=OkODsP1XDKgR0qeY&t=1723s | AA15: =TRIM(E15)&TRIM(D15) -> YUILaugh away
A16: =ROW()-1 -> 15 | B16: 4 | C16: 0:35:56 | D16: flos | E16: R Sound Design feat.初音ミク | G16: =_xlfn.XLOOKUP(B16,M_YT_LIVE!A:A,M_YT_LIVE!F:F,"ERROR",0,1) -> 弾き語り | W16: =TIMEVALUE($C16)*86400 -> 2156 | X16: =_xlfn.XLOOKUP($B16,M_YT_LIVE!$A:$A,M_YT_LIVE!$D:$D) -> https://www.youtube.com/live/qX9bxWpkH6E?si=OkODsP1XDKgR0qeY | Z16: =HYPERLINK($X16&SUBSTITUTE(マスタ!$C$3,"XXXXX",$W16)) -> https://www.youtube.com/live/qX9bxWpkH6E?si=OkODsP1XDKgR0qeY&t=2156s | AA16: =TRIM(E16)&TRIM(D16) -> R Sound Design feat.初音ミクflos
... A596: =ROW()-1 -> 595 | B596: 84 | C596: 1:19:16 | D596: 恋なんて | E596: 羊文学 | G596: =_xlfn.XLOOKUP(B596,M_YT_LIVE!A:A,M_YT_LIVE!F:F,"ERROR",0,1) -> 弾き語り | W596: =TIMEVALUE($C596)*86400 -> 4756 | X596: =_xlfn.XLOOKUP($B596,M_YT_LIVE!$A:$A,M_YT_LIVE!$D:$D) -> https://www.youtube.com/live/r7Bwk1jHwnc?si=YSwS6uQI_0X3Y91g | Z596: =HYPERLINK($X596&SUBSTITUTE(マスタ!$C$3,"XXXXX",$W596)) -> https://www.youtube.com/live/r7Bwk1jHwnc?si=YSwS6uQI_0X3Y91g&t=4756s | AA596: =TRIM(E596)&TRIM(D596) -> 羊文学恋なんて
A597: =ROW()-1 -> 596 | B597: 84 | C597: 1:30:25 | D597: Sincerely | E597: TRUE | G597: =_xlfn.XLOOKUP(B597,M_YT_LIVE!A:A,M_YT_LIVE!F:F,"ERROR",0,1) -> 弾き語り | W597: =TIMEVALUE($C597)*86400 -> 5425 | X597: =_xlfn.XLOOKUP($B597,M_YT_LIVE!$A:$A,M_YT_LIVE!$D:$D) -> https://www.youtube.com/live/r7Bwk1jHwnc?si=YSwS6uQI_0X3Y91g | Z597: =HYPERLINK($X597&SUBSTITUTE(マスタ!$C$3,"XXXXX",$W597)) -> https://www.youtube.com/live/r7Bwk1jHwnc?si=YSwS6uQI_0X3Y91g&t=5425s | AA597: =TRIM(E597)&TRIM(D597) -> TRUESincerely
A598: =ROW()-1 -> 597 | B598: 84 | C598: 1:41:20 | D598: Harvest | E598: (K)NoW_NAME | G598: =_xlfn.XLOOKUP(B598,M_YT_LIVE!A:A,M_YT_LIVE!F:F,"ERROR",0,1) -> 弾き語り | W598: =TIMEVALUE($C598)*86400 -> 6080 | X598: =_xlfn.XLOOKUP($B598,M_YT_LIVE!$A:$A,M_YT_LIVE!$D:$D) -> https://www.youtube.com/live/r7Bwk1jHwnc?si=YSwS6uQI_0X3Y91g | Z598: =HYPERLINK($X598&SUBSTITUTE(マスタ!$C$3,"XXXXX",$W598)) -> https://www.youtube.com/live/r7Bwk1jHwnc?si=YSwS6uQI_0X3Y91g&t=6080s | AA598: =TRIM(E598)&TRIM(D598) -> (K)NoW_NAMEHarvest
A599: =ROW()-1 -> 598 | B599: 85 | C599: 0:05:29 | D599: 少女レイ | E599: みきとP feat.初音ミク | G599: =_xlfn.XLOOKUP(B599,M_YT_LIVE!A:A,M_YT_LIVE!F:F,"ERROR",0,1) -> 弾き語り&音源 | W599: =TIMEVALUE($C599)*86400 -> 329 | X599: =_xlfn.XLOOKUP($B599,M_YT_LIVE!$A:$A,M_YT_LIVE!$D:$D) -> https://www.youtube.com/live/b0qPGU0sZn4?si=C5mabzVl6bhK7mp0 | Z599: =HYPERLINK($X599&SUBSTITUTE(マスタ!$C$3,"XXXXX",$W599)) -> https://www.youtube.com/live/b0qPGU0sZn4?si=C5mabzVl6bhK7mp0&t=329s | AA599: =TRIM(E599)&TRIM(D599) -> みきとP feat.初音ミク少女レイ
A600: =ROW()-1 -> 599 | B600: 85 | C600: 0:13:11 | D600: 火星人 | E600: ヨルシカ | G600: =_xlfn.XLOOKUP(B600,M_YT_LIVE!A:A,M_YT_LIVE!F:F,"ERROR",0,1) -> 弾き語り&音源 | W600: =TIMEVALUE($C600)*86400 -> 791 | X600: =_xlfn.XLOOKUP($B600,M_YT_LIVE!$A:$A,M_YT_LIVE!$D:$D) -> https://www.youtube.com/live/b0qPGU0sZn4?si=C5mabzVl6bhK7mp0 | Z600: =HYPERLINK($X600&SUBSTITUTE(マスタ!$C$3,"XXXXX",$W600)) -> https://www.youtube.com/live/b0qPGU0sZn4?si=C5mabzVl6bhK7mp0&t=791s | AA600: =TRIM(E600)&TRIM(D600) -> ヨルシカ火星人
A601: =ROW()-1 -> 600 | B601: 85 | C601: 0:19:49 | D601: 夢灯篭 | E601: RADWIMPS | G601: =_xlfn.XLOOKUP(B601,M_YT_LIVE!A:A,M_YT_LIVE!F:F,"ERROR",0,1) -> 弾き語り&音源 | W601: =TIMEVALUE($C601)*86400 -> 1189 | X601: =_xlfn.XLOOKUP($B601,M_YT_LIVE!$A:$A,M_YT_LIVE!$D:$D) -> https://www.youtube.com/live/b0qPGU0sZn4?si=C5mabzVl6bhK7mp0 | Z601: =HYPERLINK($X601&SUBSTITUTE(マスタ!$C$3,"XXXXX",$W601)) -> https://www.youtube.com/live/b0qPGU0sZn4?si=C5mabzVl6bhK7mp0&t=1189s | AA601: =TRIM(E601)&TRIM(D601) -> RADWIMPS夢灯篭
A602: =ROW()-1 -> 601 | B602: 85 | C602: 0:23:54 | D602: スパークル | E602: RADWIMPS | G602: =_xlfn.XLOOKUP(B602,M_YT_LIVE!A:A,M_YT_LIVE!F:F,"ERROR",0,1) -> 弾き語り&音源 | W602: =TIMEVALUE($C602)*86400 -> 1434 | X602: =_xlfn.XLOOKUP($B602,M_YT_LIVE!$A:$A,M_YT_LIVE!$D:$D) -> https://www.youtube.com/live/b0qPGU0sZn4?si=C5mabzVl6bhK7mp0 | Z602: =HYPERLINK($X602&SUBSTITUTE(マスタ!$C$3,"XXXXX",$W602)) -> https://www.youtube.com/live/b0qPGU0sZn4?si=C5mabzVl6bhK7mp0&t=1434s | AA602: =TRIM(E602)&TRIM(D602) -> RADWIMPSスパークル
A603: =ROW()-1 -> 602 | B603: 85 | C603: 0:31:51 | D603: Feel | E603: 羊文学 | G603: =_xlfn.XLOOKUP(B603,M_YT_LIVE!A:A,M_YT_LIVE!F:F,"ERROR",0,1) -> 弾き語り&音源 | W603: =TIMEVALUE($C603)*86400 -> 1911 | X603: =_xlfn.XLOOKUP($B603,M_YT_LIVE!$A:$A,M_YT_LIVE!$D:$D) -> https://www.youtube.com/live/b0qPGU0sZn4?si=C5mabzVl6bhK7mp0 | Z603: =HYPERLINK($X603&SUBSTITUTE(マスタ!$C$3,"XXXXX",$W603)) -> https://www.youtube.com/live/b0qPGU0sZn4?si=C5mabzVl6bhK7mp0&t=1911s | AA603: =TRIM(E603)&TRIM(D603) -> 羊文学Feel
A604: =ROW()-1 -> 603 | B604: 85 | C604: 0:37:42 | D604: 恋なんて | E604: 羊文学 | G604: =_xlfn.XLOOKUP(B604,M_YT_LIVE!A:A,M_YT_LIVE!F:F,"ERROR",0,1) -> 弾き語り&音源 | W604: =TIMEVALUE($C604)*86400 -> 2262 | X604: =_xlfn.XLOOKUP($B604,M_YT_LIVE!$A:$A,M_YT_LIVE!$D:$D) -> https://www.youtube.com/live/b0qPGU0sZn4?si=C5mabzVl6bhK7mp0 | Z604: =HYPERLINK($X604&SUBSTITUTE(マスタ!$C$3,"XXXXX",$W604)) -> https://www.youtube.com/live/b0qPGU0sZn4?si=C5mabzVl6bhK7mp0&t=2262s | AA604: =TRIM(E604)&TRIM(D604) -> 羊文学恋なんて
A605: =ROW()-1 -> 604 | B605: 85 | C605: 0:43:54 | D605: 永遠のブルー | E605: 羊文学 | G605: =_xlfn.XLOOKUP(B605,M_YT_LIVE!A:A,M_YT_LIVE!F:F,"ERROR",0,1) -> 弾き語り&音源 | W605: =TIMEVALUE($C605)*86400 -> 2634 | X605: =_xlfn.XLOOKUP($B605,M_YT_LIVE!$A:$A,M_YT_LIVE!$D:$D) -> https://www.youtube.com/live/b0qPGU0sZn4?si=C5mabzVl6bhK7mp0 | Z605: =HYPERLINK($X605&SUBSTITUTE(マスタ!$C$3,"XXXXX",$W605)) -> https://www.youtube.com/live/b0qPGU0sZn4?si=C5mabzVl6bhK7mp0&t=2634s | AA605: =TRIM(E605)&TRIM(D605) -> 羊文学永遠のブルー
A606: =ROW()-1 -> 605 | B606: 85 | C606: 0:49:05 | D606: more than words | E606: 羊文学 | G606: =_xlfn.XLOOKUP(B606,M_YT_LIVE!A:A,M_YT_LIVE!F:F,"ERROR",0,1) -> 弾き語り&音源 | W606: =TIMEVALUE($C606)*86400 -> 2945 | X606: =_xlfn.XLOOKUP($B606,M_YT_LIVE!$A:$A,M_YT_LIVE!$D:$D) -> https://www.youtube.com/live/b0qPGU0sZn4?si=C5mabzVl6bhK7mp0 | Z606: =HYPERLINK($X606&SUBSTITUTE(マスタ!$C$3,"XXXXX",$W606)) -> https://www.youtube.com/live/b0qPGU0sZn4?si=C5mabzVl6bhK7mp0&t=2945s | AA606: =TRIM(E606)&TRIM(D606) -> 羊文学more than words
A607: =ROW()-1 -> 606 | B607: 85 | C607: 0:58:38 | D607: 春を待つ | E607: lslet feat.倚水 | G607: =_xlfn.XLOOKUP(B607,M_YT_LIVE!A:A,M_YT_LIVE!F:F,"ERROR",0,1) -> 弾き語り&音源 | W607: =TIMEVALUE($C607)*86400 -> 3518 | X607: =_xlfn.XLOOKUP($B607,M_YT_LIVE!$A:$A,M_YT_LIVE!$D:$D) -> https://www.youtube.com/live/b0qPGU0sZn4?si=C5mabzVl6bhK7mp0 | Z607: =HYPERLINK($X607&SUBSTITUTE(マスタ!$C$3,"XXXXX",$W607)) -> https://www.youtube.com/live/b0qPGU0sZn4?si=C5mabzVl6bhK7mp0&t=3518s | AA607: =TRIM(E607)&TRIM(D607) -> lslet feat.倚水春を待つ
A608: =ROW()-1 -> 607 | B608: 85 | C608: 1:05:44 | D608: 晴れるなら | E608: Guiano | G608: =_xlfn.XLOOKUP(B608,M_YT_LIVE!A:A,M_YT_LIVE!F:F,"ERROR",0,1) -> 弾き語り&音源 | W608: =TIMEVALUE($C608)*86400 -> 3944 | X608: =_xlfn.XLOOKUP($B608,M_YT_LIVE!$A:$A,M_YT_LIVE!$D:$D) -> https://www.youtube.com/live/b0qPGU0sZn4?si=C5mabzVl6bhK7mp0 | Z608: =HYPERLINK($X608&SUBSTITUTE(マスタ!$C$3,"XXXXX",$W608)) -> https://www.youtube.com/live/b0qPGU0sZn4?si=C5mabzVl6bhK7mp0&t=3944s | AA608: =TRIM(E608)&TRIM(D608) -> Guiano晴れるなら
A609: =ROW()-1 -> 608 | B609: 85 | C609: 1:11:23 | D609: 隙 | E609: ユーリ | G609: =_xlfn.XLOOKUP(B609,M_YT_LIVE!A:A,M_YT_LIVE!F:F,"ERROR",0,1) -> 弾き語り&音源 | W609: =TIMEVALUE($C609)*86400 -> 4283 | X609: =_xlfn.XLOOKUP($B609,M_YT_LIVE!$A:$A,M_YT_LIVE!$D:$D) -> https://www.youtube.com/live/b0qPGU0sZn4?si=C5mabzVl6bhK7mp0 | Z609: =HYPERLINK($X609&SUBSTITUTE(マスタ!$C$3,"XXXXX",$W609)) -> https://www.youtube.com/live/b0qPGU0sZn4?si=C5mabzVl6bhK7mp0&t=4283s | AA609: =TRIM(E609)&TRIM(D609) -> ユーリ隙
... A814: =ROW()-1 -> 813 | B814: 106 | C814: 2:03:55 | D814: 残灯花火 | E814: Orangestar feat.初音ミク | G814: =_xlfn.XLOOKUP(B814,M_YT_LIVE!A:A,M_YT_LIVE!F:F,"ERROR",0,1) -> 弾き語り | W814: =TIMEVALUE($C814)*86400 -> 7435 | X814: =_xlfn.XLOOKUP($B814,M_YT_LIVE!$A:$A,M_YT_LIVE!$D:$D) -> https://www.youtube.com/live/B1g4NIZAKqo?si=v8CWAz6GBo-vVIKK | Z814: =HYPERLINK($X814&SUBSTITUTE(マスタ!$C$3,"XXXXX",$W814)) -> https://www.youtube.com/live/B1g4NIZAKqo?si=v8CWAz6GBo-vVIKK&t=7435s | AA814: =TRIM(E814)&TRIM(D814) -> Orangestar feat.初音ミク残灯花火
A815: =ROW()-1 -> 814 | G815: =_xlfn.XLOOKUP(B815,M_YT_LIVE!A:A,M_YT_LIVE!F:F,"ERROR",0,1) -> 0 | W815: =TIMEVALUE($C815)*86400 -> #VALUE! | X815: =_xlfn.XLOOKUP($B815,M_YT_LIVE!$A:$A,M_YT_LIVE!$D:$D) -> 0 | Z815: =HYPERLINK($X815&SUBSTITUTE(マスタ!$C$3,"XXXXX",$W815)) -> #VALUE! | AA815: =TRIM(E815)&TRIM(D815)
A816: =ROW()-1 -> 815 | G816: =_xlfn.XLOOKUP(B816,M_YT_LIVE!A:A,M_YT_LIVE!F:F,"ERROR",0,1) -> 0 | W816: =TIMEVALUE($C816)*86400 -> #VALUE! | X816: =_xlfn.XLOOKUP($B816,M_YT_LIVE!$A:$A,M_YT_LIVE!$D:$D) -> 0 | Z816: =HYPERLINK($X816&SUBSTITUTE(マスタ!$C$3,"XXXXX",$W816)) -> #VALUE! | AA816: =TRIM(E816)&TRIM(D816)
A817: =ROW()-1 -> 816 | G817: =_xlfn.XLOOKUP(B817,M_YT_LIVE!A:A,M_YT_LIVE!F:F,"ERROR",0,1) -> 0 | W817: =TIMEVALUE($C817)*86400 -> #VALUE! | X817: =_xlfn.XLOOKUP($B817,M_YT_LIVE!$A:$A,M_YT_LIVE!$D:$D) -> 0 | Z817: =HYPERLINK($X817&SUBSTITUTE(マスタ!$C$3,"XXXXX",$W817)) -> #VALUE! | AA817: =TRIM(E817)&TRIM(D817)
A818: =ROW()-1 -> 817 | G818: =_xlfn.XLOOKUP(B818,M_YT_LIVE!A:A,M_YT_LIVE!F:F,"ERROR",0,1) -> 0 | W818: =TIMEVALUE($C818)*86400 -> #VALUE! | X818: =_xlfn.XLOOKUP($B818,M_YT_LIVE!$A:$A,M_YT_LIVE!$D:$D) -> 0 | Z818: =HYPERLINK($X818&SUBSTITUTE(マスタ!$C$3,"XXXXX",$W818)) -> #VALUE! | AA818: =TRIM(E818)&TRIM(D818)
A819: =ROW()-1 -> 818 | G819: =_xlfn.XLOOKUP(B819,M_YT_LIVE!A:A,M_YT_LIVE!F:F,"ERROR",0,1) -> 0 | W819: =TIMEVALUE($C819)*86400 -> #VALUE! | X819: =_xlfn.XLOOKUP($B819,M_YT_LIVE!$A:$A,M_YT_LIVE!$D:$D) -> 0 | Z819: =HYPERLINK($X819&SUBSTITUTE(マスタ!$C$3,"XXXXX",$W819)) -> #VALUE! | AA819: =TRIM(E819)&TRIM(D819)
A820: =ROW()-1 -> 819 | G820: =_xlfn.XLOOKUP(B820,M_YT_LIVE!A:A,M_YT_LIVE!F:F,"ERROR",0,1) -> 0 | W820: =TIMEVALUE($C820)*86400 -> #VALUE! | X820: =_xlfn.XLOOKUP($B820,M_YT_LIVE!$A:$A,M_YT_LIVE!$D:$D) -> 0 | Z820: =HYPERLINK($X820&SUBSTITUTE(マスタ!$C$3,"XXXXX",$W820)) -> #VALUE! | AA820: =TRIM(E820)&TRIM(D820)
A821: =ROW()-1 -> 820 | G821: =_xlfn.XLOOKUP(B821,M_YT_LIVE!A:A,M_YT_LIVE!F:F,"ERROR",0,1) -> 0 | W821: =TIMEVALUE($C821)*86400 -> #VALUE! | X821: =_xlfn.XLOOKUP($B821,M_YT_LIVE!$A:$A,M_YT_LIVE!$D:$D) -> 0 | Z821: =HYPERLINK($X821&SUBSTITUTE(マスタ!$C$3,"XXXXX",$W821)) -> #VALUE! | AA821: =TRIM(E821)&TRIM(D821)
A822: =ROW()-1 -> 821 | G822: =_xlfn.XLOOKUP(B822,M_YT_LIVE!A:A,M_YT_LIVE!F:F,"ERROR",0,1) -> 0 | W822: =TIMEVALUE($C822)*86400 -> #VALUE! | X822: =_xlfn.XLOOKUP($B822,M_YT_LIVE!$A:$A,M_YT_LIVE!$D:$D) -> 0 | Z822: =HYPERLINK($X822&SUBSTITUTE(マスタ!$C$3,"XXXXX",$W822)) -> #VALUE! | AA822: =TRIM(E822)&TRIM(D822)
A823: =ROW()-1 -> 822 | G823: =_xlfn.XLOOKUP(B823,M_YT_LIVE!A:A,M_YT_LIVE!F:F,"ERROR",0,1) -> 0 | W823: =TIMEVALUE($C823)*86400 -> #VALUE! | X823: =_xlfn.XLOOKUP($B823,M_YT_LIVE!$A:$A,M_YT_LIVE!$D:$D) -> 0 | Z823: =HYPERLINK($X823&SUBSTITUTE(マスタ!$C$3,"XXXXX",$W823)) -> #VALUE! | AA823: =TRIM(E823)&TRIM(D823)
...

Sheet V_SONG_LIST
C1: key | AA1: アーティスト | AB1: アーティスト(ソート用) | AC1: 曲名 | AD1: 最近の歌唱
A2: {=_xlfn._xlws.SORT(_xlfn.UNIQUE(_xlfn._xlws.FILTER(M_YT_LIVE_TIMESTAMP!D:E, (ISERROR(SEARCH("-", M_YT_LIVE_TIMESTAMP!E:E)))*(M_YT_LIVE_TIMESTAMP!D:D<>0)*(M_YT_LIVE_TIMESTAMP!E:E<>"アーティスト")*(M_YT_LIVE_TIMESTAMP!D:D<>"曲名")*(M_YT_LIVE_TIMESTAMP!E:E<>0))), {2,1}, 1)} -> Harvest | B2: (K)NoW_NAME | C2: =TRIM(B2)&TRIM(A2) -> (K)NoW_NAMEHarvest | AA2: =B2 -> (K)NoW_NAME | AB2: =_xlfn.XLOOKUP(AA2,M_ARTIST!A:A,M_ARTIST!B:B,"★★★",0,1) -> K NoW_NAME | AC2: =A2 -> Harvest | AD2: =HYPERLINK(_xlfn.XLOOKUP(C2,M_YT_LIVE_TIMESTAMP!AA:AA,M_YT_LIVE_TIMESTAMP!Z:Z,"★",0,-1)) -> https://www.youtube.com/live/r7Bwk1jHwnc?si=YSwS6uQI_0X3Y91g&t=6080s
A3: Heal Me | B3: *Luna feat.マクネナナ | C3: =TRIM(B3)&TRIM(A3) -> *Luna feat.マクネナナHeal Me | AA3: =B3 -> *Luna feat.マクネナナ | AB3: =_xlfn.XLOOKUP(AA3,M_ARTIST!A:A,M_ARTIST!B:B,"★★★",0,1) -> Luna feat.まくねなな | AC3: =A3 -> Heal Me | AD3: =HYPERLINK(_xlfn.XLOOKUP(C3,M_YT_LIVE_TIMESTAMP!AA:AA,M_YT_LIVE_TIMESTAMP!Z:Z,"★",0,-1)) -> https://www.youtube.com/live/w8cj1TZhgIM?si=jSw7OZzFwM2n4KKP&t=1214s
A4: SNOW SOUND | B4: [Alexandros] | C4: =TRIM(B4)&TRIM(A4) -> [Alexandros]SNOW SOUND | AA4: =B4 -> [Alexandros] | AB4: =_xlfn.XLOOKUP(AA4,M_ARTIST!A:A,M_ARTIST!B:B,"★★★",0,1) -> Alexandros | AC4: =A4 -> SNOW SOUND | AD4: =HYPERLINK(_xlfn.XLOOKUP(C4,M_YT_LIVE_TIMESTAMP!AA:AA,M_YT_LIVE_TIMESTAMP!Z:Z,"★",0,-1)) -> https://www.youtube.com/live/w3oM0fDmwz4?si=VVO-ga6uipBLMrpR&t=6550s
A5: ワタリドリ | B5: [Alexandros] | C5: =TRIM(B5)&TRIM(A5) -> [Alexandros]ワタリドリ | AA5: =B5 -> [Alexandros] | AB5: =_xlfn.XLOOKUP(AA5,M_ARTIST!A:A,M_ARTIST!B:B,"★★★",0,1) -> Alexandros | AC5: =A5 -> ワタリドリ | AD5: =HYPERLINK(_xlfn.XLOOKUP(C5,M_YT_LIVE_TIMESTAMP!AA:AA,M_YT_LIVE_TIMESTAMP!Z:Z,"★",0,-1)) -> https://www.youtube.com/live/rowkHJneOgY?si=dzvDO_qNHD4fLHMQ&t=5138s
A6: 天ノ弱 | B6: 164P feat.GUMI | C6: =TRIM(B6)&TRIM(A6) -> 164P feat.GUMI天ノ弱 | AA6: =B6 -> 164P feat.GUMI | AB6: =_xlfn.XLOOKUP(AA6,M_ARTIST!A:A,M_ARTIST!B:B,"★★★",0,1) -> 164P feat.GUMI | AC6: =A6 -> 天ノ弱 | AD6: =HYPERLINK(_xlfn.XLOOKUP(C6,M_YT_LIVE_TIMESTAMP!AA:AA,M_YT_LIVE_TIMESTAMP!Z:Z,"★",0,-1)) -> https://www.youtube.com/live/OYaf_O-6WRs?si=20Zo4VVa8PxJbw_X&t=3788s
A7: 化けの花 | B7: 25時、ナイトコードで。×KAITO | C7: =TRIM(B7)&TRIM(A7) -> 25時、ナイトコードで。×KAITO化けの花 | AA7: =B7 -> 25時、ナイトコードで。×KAITO | AB7: =_xlfn.XLOOKUP(AA7,M_ARTIST!A:A,M_ARTIST!B:B,"★★★",0,1) -> 25じ、ないとこーどで。x KAITO | AC7: =A7 -> 化けの花 | AD7: =HYPERLINK(_xlfn.XLOOKUP(C7,M_YT_LIVE_TIMESTAMP!AA:AA,M_YT_LIVE_TIMESTAMP!Z:Z,"★",0,-1)) -> https://www.youtube.com/live/b0qPGU0sZn4?si=C5mabzVl6bhK7mp0&t=6558s
A8: 化けの花(1chorus) | B8: 25時、ナイトコードで。×KAITO | C8: =TRIM(B8)&TRIM(A8) -> 25時、ナイトコードで。×KAITO化けの花(1chorus) | AA8: =B8 -> 25時、ナイトコードで。×KAITO | AB8: =_xlfn.XLOOKUP(AA8,M_ARTIST!A:A,M_ARTIST!B:B,"★★★",0,1) -> 25じ、ないとこーどで。x KAITO | AC8: =A8 -> 化けの花(1chorus) | AD8: =HYPERLINK(_xlfn.XLOOKUP(C8,M_YT_LIVE_TIMESTAMP!AA:AA,M_YT_LIVE_TIMESTAMP!Z:Z,"★",0,-1)) -> https://www.youtube.com/live/OEtLBen9pLM?si=M4WDMSGkkHfWLvDr&t=4372s
A9: からくりピエロ | B9: 40mP feat.初音ミク | C9: =TRIM(B9)&TRIM(A9) -> 40mP feat.初音ミクからくりピエロ | AA9: =B9 -> 40mP feat.初音ミク | AB9: =_xlfn.XLOOKUP(AA9,M_ARTIST!A:A,M_ARTIST!B:B,"★★★",0,1) -> 40mP feat.はつねみく | AC9: =A9 -> からくりピエロ | AD9: =HYPERLINK(_xlfn.XLOOKUP(C9,M_YT_LIVE_TIMESTAMP!AA:AA,M_YT_LIVE_TIMESTAMP!Z:Z,"★",0,-1)) -> https://www.youtube.com/live/i7euCqiwzl4?si=Gvd-dBAI4nZ9HDpv&t=325s
A10: トリノコシティ | B10: 40mP feat.初音ミク | C10: =TRIM(B10)&TRIM(A10) -> 40mP feat.初音ミクトリノコシティ | AA10: =B10 -> 40mP feat.初音ミク | AB10: =_xlfn.XLOOKUP(AA10,M_ARTIST!A:A,M_ARTIST!B:B,"★★★",0,1) -> 40mP feat.はつねみく | AC10: =A10 -> トリノコシティ | AD10: =HYPERLINK(_xlfn.XLOOKUP(C10,M_YT_LIVE_TIMESTAMP!AA:AA,M_YT_LIVE_TIMESTAMP!Z:Z,"★",0,-1)) -> https://www.youtube.com/live/w3oM0fDmwz4?si=VVO-ga6uipBLMrpR&t=3567s
A11: 純情スカート | B11: 40mP feat.初音ミク | C11: =TRIM(B11)&TRIM(A11) -> 40mP feat.初音ミク純情スカート | AA11: =B11 -> 40mP feat.初音ミク | AB11: =_xlfn.XLOOKUP(AA11,M_ARTIST!A:A,M_ARTIST!B:B,"★★★",0,1) -> 40mP feat.はつねみく | AC11: =A11 -> 純情スカート | AD11: =HYPERLINK(_xlfn.XLOOKUP(C11,M_YT_LIVE_TIMESTAMP!AA:AA,M_YT_LIVE_TIMESTAMP!Z:Z,"★",0,-1)) -> https://www.youtube.com/live/bXG5ottJZas?si=VsjzjU8RreUrJGd3&t=4397s
A12: 恋愛裁判 | B12: 40mP feat.初音ミク | C12: =TRIM(B12)&TRIM(A12) -> 40mP feat.初音ミク恋愛裁判 | AA12: =B12 -> 40mP feat.初音ミク | AB12: =_xlfn.XLOOKUP(AA12,M_ARTIST!A:A,M_ARTIST!B:B,"★★★",0,1) -> 40mP feat.はつねみく | AC12: =A12 -> 恋愛裁判 | AD12: =HYPERLINK(_xlfn.XLOOKUP(C12,M_YT_LIVE_TIMESTAMP!AA:AA,M_YT_LIVE_TIMESTAMP!Z:Z,"★",0,-1)) -> https://www.youtube.com/live/EIV2fME4Fec?si=lkzDtJEJ9agzd2Md&t=4734s
A13: フタリボシ | B13: 40mP feat.初音ミク&GUMI | C13: =TRIM(B13)&TRIM(A13) -> 40mP feat.初音ミク&GUMIフタリボシ | AA13: =B13 -> 40mP feat.初音ミク&GUMI | AB13: =_xlfn.XLOOKUP(AA13,M_ARTIST!A:A,M_ARTIST!B:B,"★★★",0,1) -> 40mP feat.はつねみく&GUMI | AC13: =A13 -> フタリボシ | AD13: =HYPERLINK(_xlfn.XLOOKUP(C13,M_YT_LIVE_TIMESTAMP!AA:AA,M_YT_LIVE_TIMESTAMP!Z:Z,"★",0,-1)) -> https://www.youtube.com/live/keSRwH4Zr7g?si=RPmDxNZjQB1dZWSK&t=611s
A14: うっせぇわ | B14: Ado | C14: =TRIM(B14)&TRIM(A14) -> Adoうっせぇわ | AA14: =B14 -> Ado | AB14: =_xlfn.XLOOKUP(AA14,M_ARTIST!A:A,M_ARTIST!B:B,"★★★",0,1) -> Ado | AC14: =A14 -> うっせぇわ | AD14: =HYPERLINK(_xlfn.XLOOKUP(C14,M_YT_LIVE_TIMESTAMP!AA:AA,M_YT_LIVE_TIMESTAMP!Z:Z,"★",0,-1)) -> https://www.youtube.com/live/Yti72SsHzxs?si=qlI2gfa0I0wWYoH4&t=2350s
... A474: Butter-Fly(1phrase) | B474: 和田光司 | C474: =TRIM(B474)&TRIM(A474) -> 和田光司Butter-Fly(1phrase) | AA474: =B474 -> 和田光司 | AB474: =_xlfn.XLOOKUP(AA474,M_ARTIST!A:A,M_ARTIST!B:B,"★★★",0,1) -> わだこうじ | AC474: =A474 -> Butter-Fly(1phrase) | AD474: =HYPERLINK(_xlfn.XLOOKUP(C474,M_YT_LIVE_TIMESTAMP!AA:AA,M_YT_LIVE_TIMESTAMP!Z:Z,"★",0,-1)) -> https://www.youtube.com/live/8yfLYQayxQg?si=O0Q0AXQXC39nd7WJ&t=7822s
A475: Sincerely | B475: TRUE | C475: =TRIM(B475)&TRIM(A475) -> TRUESincerely | AA475: =B475 -> TRUE | AB475: =_xlfn.XLOOKUP(AA475,M_ARTIST!A:A,M_ARTIST!B:B,"★★★",0,1) -> TRUE | AC475: =A475 -> Sincerely | AD475: =HYPERLINK(_xlfn.XLOOKUP(C475,M_YT_LIVE_TIMESTAMP!AA:AA,M_YT_LIVE_TIMESTAMP!Z:Z,"★",0,-1)) -> https://www.youtube.com/live/r7Bwk1jHwnc?si=YSwS6uQI_0X3Y91g&t=5425s
C476: =TRIM(B476)&TRIM(A476) | AA476: =B476 -> 0 | AB476: =_xlfn.XLOOKUP(AA476,M_ARTIST!A:A,M_ARTIST!B:B,"★★★",0,1) -> ★★★ | AC476: =A476 -> 0 | AD476: =HYPERLINK(_xlfn.XLOOKUP(C476,M_YT_LIVE_TIMESTAMP!AA:AA,M_YT_LIVE_TIMESTAMP!Z:Z,"★",0,-1)) -> #VALUE!
C477: =TRIM(B477)&TRIM(A477) | AA477: =B477 -> 0 | AB477: =_xlfn.XLOOKUP(AA477,M_ARTIST!A:A,M_ARTIST!B:B,"★★★",0,1) -> ★★★ | AC477: =A477 -> 0 | AD477: =HYPERLINK(_xlfn.XLOOKUP(C477,M_YT_LIVE_TIMESTAMP!AA:AA,M_YT_LIVE_TIMESTAMP!Z:Z,"★",0,-1)) -> #VALUE!
C478: =TRIM(B478)&TRIM(A478) | AA478: =B478 -> 0 | AB478: =_xlfn.XLOOKUP(AA478,M_ARTIST!A:A,M_ARTIST!B:B,"★★★",0,1) -> ★★★ | AC478: =A478 -> 0 | AD478: =HYPERLINK(_xlfn.XLOOKUP(C478,M_YT_LIVE_TIMESTAMP!AA:AA,M_YT_LIVE_TIMESTAMP!Z:Z,"★",0,-1)) -> #VALUE!
C479: =TRIM(B479)&TRIM(A479) | AA479: =B479 -> 0 | AB479: =_xlfn.XLOOKUP(AA479,M_ARTIST!A:A,M_ARTIST!B:B,"★★★",0,1) -> ★★★ | AC479: =A479 -> 0 | AD479: =HYPERLINK(_xlfn.XLOOKUP(C479,M_YT_LIVE_TIMESTAMP!AA:AA,M_YT_LIVE_TIMESTAMP!Z:Z,"★",0,-1)) -> #VALUE!
C480: =TRIM(B480)&TRIM(A480) | AA480: =B480 -> 0 | AB480: =_xlfn.XLOOKUP(AA480,M_ARTIST!A:A,M_ARTIST!B:B,"★★★",0,1) -> ★★★ | AC480: =A480 -> 0 | AD480: =HYPERLINK(_xlfn.XLOOKUP(C480,M_YT_LIVE_TIMESTAMP!AA:AA,M_YT_LIVE_TIMESTAMP!Z:Z,"★",0,-1)) -> #VALUE!
C481: =TRIM(B481)&TRIM(A481) | AA481: =B481 -> 0 | AB481: =_xlfn.XLOOKUP(AA481,M_ARTIST!A:A,M_ARTIST!B:B,"★★★",0,1) -> ★★★ | AC481: =A481 -> 0 | AD481: =HYPERLINK(_xlfn.XLOOKUP(C481,M_YT_LIVE_TIMESTAMP!AA:AA,M_YT_LIVE_TIMESTAMP!Z:Z,"★",0,-1)) -> #VALUE!
C482: =TRIM(B482)&TRIM(A482) | AA482: =B482 -> 0 | AB482: =_xlfn.XLOOKUP(AA482,M_ARTIST!A:A,M_ARTIST!B:B,"★★★",0,1) -> ★★★ | AC482: =A482 -> 0 | AD482: =HYPERLINK(_xlfn.XLOOKUP(C482,M_YT_LIVE_TIMESTAMP!AA:AA,M_YT_LIVE_TIMESTAMP!Z:Z,"★",0,-1)) -> #VALUE!
C483: =TRIM(B483)&TRIM(A483) | AA483: =B483 -> 0 | AB483: =_xlfn.XLOOKUP(AA483,M_ARTIST!A:A,M_ARTIST!B:B,"★★★",0,1) -> ★★★ | AC483: =A483 -> 0 | AD483: =HYPERLINK(_xlfn.XLOOKUP(C483,M_YT_LIVE_TIMESTAMP!AA:AA,M_YT_LIVE_TIMESTAMP!Z:Z,"★",0,-1)) -> #VALUE!
C484: =TRIM(B484)&TRIM(A484) | AA484: =B484 -> 0 | AB484: =_xlfn.XLOOKUP(AA484,M_ARTIST!A:A,M_ARTIST!B:B,"★★★",0,1) -> ★★★ | AC484: =A484 -> 0 | AD484: =HYPERLINK(_xlfn.XLOOKUP(C484,M_YT_LIVE_TIMESTAMP!AA:AA,M_YT_LIVE_TIMESTAMP!Z:Z,"★",0,-1)) -> #VALUE!
C485: =TRIM(B485)&TRIM(A485) | AA485: =B485 -> 0 | AB485: =_xlfn.XLOOKUP(AA485,M_ARTIST!A:A,M_ARTIST!B:B,"★★★",0,1) -> ★★★ | AC485: =A485 -> 0 | AD485: =HYPERLINK(_xlfn.XLOOKUP(C485,M_YT_LIVE_TIMESTAMP!AA:AA,M_YT_LIVE_TIMESTAMP!Z:Z,"★",0,-1)) -> #VALUE!
C486: =TRIM(B486)&TRIM(A486) | AA486: =B486 -> 0 | AB486: =_xlfn.XLOOKUP(AA486,M_ARTIST!A:A,M_ARTIST!B:B,"★★★",0,1) -> ★★★ | AC486: =A486 -> 0 | AD486: =HYPERLINK(_xlfn.XLOOKUP(C486,M_YT_LIVE_TIMESTAMP!AA:AA,M_YT_LIVE_TIMESTAMP!Z:Z,"★",0,-1)) -> #VALUE!
C487: =TRIM(B487)&TRIM(A487) | AA487: =B487 -> 0 | AB487: =_xlfn.XLOOKUP(AA487,M_ARTIST!A:A,M_ARTIST!B:B,"★★★",0,1) -> ★★★ | AC487: =A487 -> 0 | AD487: =HYPERLINK(_xlfn.XLOOKUP(C487,M_YT_LIVE_TIMESTAMP!AA:AA,M_YT_LIVE_TIMESTAMP!Z:Z,"★",0,-1)) -> #VALUE!
... C1300: =TRIM(B1300)&TRIM(A1300) | AA1300: =B1300 -> 0 | AB1300: =_xlfn.XLOOKUP(AA1300,M_ARTIST!A:A,M_ARTIST!B:B,"★★★",0,1) -> ★★★ | AC1300: =A1300 -> 0 | AD1300: =HYPERLINK(_xlfn.XLOOKUP(C1300,M_YT_LIVE_TIMESTAMP!AA:AA,M_YT_LIVE_TIMESTAMP!Z:Z,"★",0,-1)) -> #VALUE!

Sheet ###

Sheet M_ARTIST
A1: アーティスト | B1: アーティスト(ソート用)
A2: (K)NoW_NAME | B2: K NoW_NAME
A3: 164P feat.GUMI | B3: 164P feat.GUMI
A4: 25時、ナイトコードで。×KAITO | B4: 25じ、ないとこーどで。x KAITO
A5: 40mP feat.初音ミク | B5: 40mP feat.はつねみく
A6: 40mP feat.初音ミク&GUMI | B6: 40mP feat.はつねみく&GUMI
A7: Ado | B7: Ado
A8: aiko | B8: aiko
A9: Aimer | B9: Aimer
A10: Alexandros | B10: Alexandros
A11: androp | B11: androp
A12: Aqu3ra feat.flower | B12: Aqu3ra feat.flower
... A228: yama | B228: yama
A229: TRUE | B229: TRUE
A230: HoneyWorks feat.LIP×LIP(CV:内山昂輝&島﨑信長) | B230: HoneyWorks feat.LIP×LIP(CV:うちやまこうき&しまざきのぶなが)
A231: lslet feat.倚水 | B231: lslet feat.いすい
A232: P丸様。 | B232: Pまるさま。
A233: いよわ feat.可不 | B233: いよわ feat.かふ
A234: じん feat.IA | B234: じん feat.IA
A235: ナナヲアカリ feat.Sou | B235: ななおあかり feat.Sou
A236: ユーリ | B236: ゆーり
A237: れるりり feat.GUMI | B237: れるりり feat.GUMI
A238: 絢香 | B238: あやか
A239: 神田沙也加&松たか子 | B239: かんださやか&まつたかこ
A240: 蝶々P feat.初音ミク | B240: ちょうちょうP feat.はつねみく
A241: 椎名もた feat.初音ミク | B241: しいなもた feat.はつねみく
A242: 嵐 | B242: あらし

Sheet マスタ
A1: ID | B1: 項目 | C1: 値
A2: =ROW()-1 -> 1 | B2: 時分秒変換 | C2: 86400
A3: =ROW()-1 -> 2 | B3: URL | C3: &t=XXXXXs
A4: =ROW()-1 -> 3
A5: =ROW()-1 -> 4
